<robot name="uav">

    <material name="gray">
        <color rgba=".7 .7 .7 1" />
    </material>

    <link name="body">
        <visual>
            <origin rpy="0 -1.57 0"/>
            <geometry>
                <cylinder radius=".2" length="1.3"/>
            </geometry>
            <material name="gray"/>
        </visual>
        <collision>
            <origin rpy="0 -1.57 0"/>
            <geometry>
                <cylinder radius=".2" length="1"/>
            </geometry>
            <contact_coefficient mu="0" kp="1000.0" kd="1.0"/>
        </collision>
    </link>

    <link name="head">
        <visual>
            <origin xyz="0 0 0" rpy="0 -1.57 0"/>
            <geometry>
                <sphere radius=".3"/>
            </geometry>
            <material name="gray"/>
        </visual>
        <collision>
            <origin xyz="0 0 0" rpy="0 -1.57 0"/>
            <geometry>
                <sphere radius=".3"/>
            </geometry>
            <contact_coefficient mu="0" kp="1000.0" kd="1.0"/>
        </collision>
    </link>

    <joint name="neck" type="fixed">
        <parent link="body"/>
        <child link="head"/>
        <origin xyz=".7 0 0"/>
    </joint>

    <link name="right_wing">
        <visual>
            <origin xyz="0 -.5 0" rpy="0 0 1.57"/>
            <geometry>
                <box size="1 .3 .1"/>
            </geometry>
            <material name="gray"/>
        </visual>
        <collision>
            <geometry>
                <box size="1 .3 .1"/>
            </geometry>
            <origin xyz="0 -.5 0" rpy="0 0 1.57"/>
            <contact_coefficient mu="0" kp="1000.0" kd="1.0"/>
        </collision>
    </link>

    <joint name="right_wing_swivel" type="continuous">
    <!-- <joint name="right_wing_swivel" type="fixed"> -->
        <origin xyz="0 0 0" rpy="0 0 0"/>
        <axis xyz="1 0 0"/>
        <parent link="body"/>
        <child link="right_wing"/>
    </joint>

    <link name="left_wing">
        <visual>
            <origin xyz="0 .5 0" rpy="0 0 -1.57"/>
            <geometry>
                <box size="1 .3 .1"/>
            </geometry>
            <material name="gray"/>
        </visual>
        <collision>
            <geometry>
                <box size="1 .3 .1"/>
            </geometry>
            <origin xyz="0 .5 0" rpy="0 0 -1.57"/>
            <collision_coefficient mu="0" kp="1000.0" kd="1.0"/>
        </collision>
    </link>

    <joint name="left_wing_swivel" type="continuous">
    <!-- <joint name="left_wing_swivel" type="fixed"> -->
        <origin xyz="0 0 0"/>
        <parent link="body"/>
        <child link="left_wing"/>
        <axis xyz="1 0 0"/>
    </joint>

    <link name="tail">
        <visual>
            <origin xyz="0 0 0" rpy="0 0 1.57"/>
            <geometry>
                <box size=".8 .2 .1"/>
            </geometry>
            <material name="gray"/>
        </visual>
        <collision>
            <origin xyz="0 0 0" rpy="0 0 1.57"/>
            <geometry>
                <box size=".8 .2 .1"/>
            </geometry>
            <collision_coefficient mu="0" kp="1000.0" kd="1.0"/>
        </collision>
    </link>

    <joint name="tail_body_swivel" type="fixed">
        <origin xyz="-.75 0 0"/>
        <parent link="body"/>
        <child link="tail"/>
    </joint>

</robot>